Workbook

Sheet DCF
A1: Company | B1: Infosys Ltd.
A2: Implied Price | B2: =B110 -> 1000.8487
A3: Current Price | B3: =B111 -> 1035
A4: Recommendation | B4: =IF(B112>0.05,"BUY",IF(B112<-0.05,"SELL","HOLD")) -> HOLD
A6: Data from: Screener.in | B6: Colour Legend: Orange - Assumptions
A8: Historical financials (INR crore) | B8: FY21A | C8: FY22A | D8: FY23A | E8: FY24A | F8: FY25A | G8: FY26A
A9: Sales | B9: ='Data Sheet'!F13 -> 100472 | C9: ='Data Sheet'!G13 -> 121641 | D9: ='Data Sheet'!H13 -> 146767 | E9: ='Data Sheet'!I13 -> 153670 | F9: ='Data Sheet'!J13 -> 162990 | G9: ='Data Sheet'!K13 -> 178650
A10: Total operating expenses | B10: =SUM('Data Sheet'!F14:F20) -> 72583 | C10: =SUM('Data Sheet'!G14:G20) -> 90150 | D10: =SUM('Data Sheet'!H14:H20) -> 111637 | E10: =SUM('Data Sheet'!I14:I20) -> 117245 | F10: =SUM('Data Sheet'!J14:J20) -> 123754 | G10: =SUM('Data Sheet'!K14:K20) -> 136370
A11: Operating profit (EBITDA) | B11: =B9-B10 -> 27889 | C11: =C9-C10 -> 31491 | D11: =D9-D10 -> 35130 | E11: =E9-E10 -> 36425 | F11: =F9-F10 -> 39236 | G11: =G9-G10 -> 42280
A12: Other income | B12: ='Data Sheet'!F21 -> 2201 | C12: ='Data Sheet'!G21 -> 2295 | D12: ='Data Sheet'!H21 -> 2701 | E12: ='Data Sheet'!I21 -> 4711 | F12: ='Data Sheet'!J21 -> 3600 | G12: ='Data Sheet'!K21 -> 3033
A13: Depreciation & amortisation | B13: ='Data Sheet'!F22 -> 3267 | C13: ='Data Sheet'!G22 -> 3476 | D13: ='Data Sheet'!H22 -> 4225 | E13: ='Data Sheet'!I22 -> 4678 | F13: ='Data Sheet'!J22 -> 4812 | G13: ='Data Sheet'!K22 -> 4902
A14: Interest | B14: ='Data Sheet'!F23 -> 195 | C14: ='Data Sheet'!G23 -> 200 | D14: ='Data Sheet'!H23 -> 284 | E14: ='Data Sheet'!I23 -> 470 | F14: ='Data Sheet'!J23 -> 416 | G14: ='Data Sheet'!K23 -> 416
A15: Profit before tax | B15: ='Data Sheet'!F24 -> 26628 | C15: ='Data Sheet'!G24 -> 30110 | D15: ='Data Sheet'!H24 -> 33322 | E15: ='Data Sheet'!I24 -> 35988 | F15: ='Data Sheet'!J24 -> 37608 | G15: ='Data Sheet'!K24 -> 39995
A16: Tax | B16: ='Data Sheet'!F25 -> 7205 | C16: ='Data Sheet'!G25 -> 7964 | D16: ='Data Sheet'!H25 -> 9214 | E16: ='Data Sheet'!I25 -> 9740 | F16: ='Data Sheet'!J25 -> 10858 | G16: ='Data Sheet'!K25 -> 10521
A17: Net profit | B17: ='Data Sheet'!F26 -> 19351 | C17: ='Data Sheet'!G26 -> 22110 | D17: ='Data Sheet'!H26 -> 24095 | E17: ='Data Sheet'!I26 -> 26233 | F17: ='Data Sheet'!J26 -> 26713 | G17: ='Data Sheet'!K26 -> 29440
A18: Net block (fixed assets) | B18: ='Data Sheet'!F48 -> 25505 | C18: ='Data Sheet'!G48 -> 25800 | D18: ='Data Sheet'!H48 -> 29225 | E18: ='Data Sheet'!I48 -> 27622 | F18: ='Data Sheet'!J48 -> 30961 | G18: ='Data Sheet'!K48 -> 33770
A19: Capital work in progress | B19: ='Data Sheet'!F49 -> 922 | C19: ='Data Sheet'!G49 -> 416 | D19: ='Data Sheet'!H49 -> 288 | E19: ='Data Sheet'!I49 -> 293 | F19: ='Data Sheet'!J49 -> 814 | G19: ='Data Sheet'!K49 -> 526
A20: Investments | B20: ='Data Sheet'!F50 -> 14205 | C20: ='Data Sheet'!G50 -> 20324 | D20: ='Data Sheet'!H50 -> 19478 | E20: ='Data Sheet'!I50 -> 24623 | F20: ='Data Sheet'!J50 -> 23541 | G20: ='Data Sheet'!K50 -> 21880
A21: Receivables | B21: ='Data Sheet'!F53 -> 19294 | C21: ='Data Sheet'!G53 -> 22698 | D21: ='Data Sheet'!H53 -> 25424 | E21: ='Data Sheet'!I53 -> 30193 | F21: ='Data Sheet'!J53 -> 31158 | G21: ='Data Sheet'!K53 -> 35234
A22: Other assets | B22: ='Data Sheet'!F51 -> 66879 | C22: ='Data Sheet'!G51 -> 70189 | D22: ='Data Sheet'!H51 -> 75605 | E22: ='Data Sheet'!I51 -> 83482 | F22: ='Data Sheet'!J51 -> 92479 | G22: ='Data Sheet'!K51 -> 98112
A23: Cash & bank | B23: ='Data Sheet'!F55 -> 24714 | C23: ='Data Sheet'!G55 -> 17472 | D23: ='Data Sheet'!H55 -> 12173 | E23: ='Data Sheet'!I55 -> 14786 | F23: ='Data Sheet'!J55 -> 24455 | G23: ='Data Sheet'!K55 -> 22201
A24: Borrowings | B24: ='Data Sheet'!F45 -> 5325 | C24: ='Data Sheet'!G45 -> 5474 | D24: ='Data Sheet'!H45 -> 8299 | E24: ='Data Sheet'!I45 -> 8359 | F24: ='Data Sheet'!J45 -> 8227 | G24: ='Data Sheet'!K45 -> 9176
A25: Other liabilities | B25: ='Data Sheet'!F46 -> 25835 | C25: ='Data Sheet'!G46 -> 35905 | D25: ='Data Sheet'!H46 -> 40890 | E25: ='Data Sheet'!I46 -> 39545 | F25: ='Data Sheet'!J46 -> 43750 | G25: ='Data Sheet'!K46 -> 52260
A26: Total equity (share capital + reserves) | B26: ='Data Sheet'!F43+'Data Sheet'!F44 -> 76351 | C26: ='Data Sheet'!G43+'Data Sheet'!G44 -> 75350 | D26: ='Data Sheet'!H43+'Data Sheet'!H44 -> 75407 | E26: ='Data Sheet'!I43+'Data Sheet'!I44 -> 88116 | F26: ='Data Sheet'!J43+'Data Sheet'!J44 -> 95818 | G26: ='Data Sheet'!K43+'Data Sheet'!K44 -> 92852
A27: Cash from operating activity | B27: ='Data Sheet'!F82 -> 23224 | C27: ='Data Sheet'!G82 -> 23885 | D27: ='Data Sheet'!H82 -> 22467 | E27: ='Data Sheet'!I82 -> 25210 | F27: ='Data Sheet'!J82 -> 35694 | G27: ='Data Sheet'!K82 -> 33986
A29: Market data
A30: Current share price (INR) | B30: ='Data Sheet'!B8 -> 1035
A31: Market capitalisation | B31: ='Data Sheet'!B9 -> 420031.63
A32: Shares outstanding (crore) | B32: ='Data Sheet'!K93 -> 405.56
A34: Derived historical metrics | B34: FY21A | C34: FY22A | D34: FY23A | E34: FY24A | F34: FY25A | G34: FY26A
A35: Revenue growth | B35: n.a. | C35: =C9/B9-1 -> 0.21069552 | D35: =D9/C9-1 -> 0.20655864 | E35: =E9/D9-1 -> 0.047033734 | F35: =F9/E9-1 -> 0.060649444 | G35: =G9/F9-1 -> 0.096079514
A36: EBITDA margin | B36: =B11/B9 -> 0.27757982 | C36: =C11/C9 -> 0.25888475 | D36: =D11/D9 -> 0.23935898 | E36: =E11/E9 -> 0.2370339 | F36: =F11/F9 -> 0.24072642 | G36: =G11/G9 -> 0.23666387
A37: EBIT (EBITDA - D&A) | B37: =B11-B13 -> 24622 | C37: =C11-C13 -> 28015 | D37: =D11-D13 -> 30905 | E37: =E11-E13 -> 31747 | F37: =F11-F13 -> 34424 | G37: =G11-G13 -> 37378
A38: EBIT margin | B38: =B37/B9 -> 0.2450633 | C38: =C37/C9 -> 0.23030886 | D38: =D37/D9 -> 0.21057186 | E38: =E37/E9 -> 0.20659205 | F38: =F37/F9 -> 0.21120314 | G38: =G37/G9 -> 0.20922474
A39: D&A % of revenue | B39: =B13/B9 -> 0.032516522 | C39: =C13/C9 -> 0.028575891 | D39: =D13/D9 -> 0.028787125 | E39: =E13/E9 -> 0.030441856 | F39: =F13/F9 -> 0.029523284 | G39: =G13/G9 -> 0.027439127
A40: Effective tax rate | B40: =B16/B15 -> 0.27057984 | C40: =C16/C15 -> 0.26449684 | D40: =D16/D15 -> 0.27651401 | E40: =E16/E15 -> 0.27064577 | F40: =F16/F15 -> 0.28871517 | G40: =G16/G15 -> 0.26305788
A41: Capex (proxy) | B41: n.a. | C41: =(C18-B18)+(C19-B19)+C13 -> 3265 | D41: =(D18-C18)+(D19-C19)+D13 -> 7522 | E41: =(E18-D18)+(E19-D19)+E13 -> 3080 | F41: =(F18-E18)+(F19-E19)+F13 -> 8672 | G41: =(G18-F18)+(G19-F19)+G13 -> 7423
A42: Capex % of revenue | B42: n.a. | C42: =C41/C9 -> 0.026841279 | D42: =D41/D9 -> 0.051251303 | E42: =E41/E9 -> 0.020042949 | F42: =F41/F9 -> 0.053205718 | G42: =G41/G9 -> 0.041550518
A43: Net working capital | B43: =B22-B23-B25 -> 16330 | C43: =C22-C23-C25 -> 16812 | D43: =D22-D23-D25 -> 22542 | E43: =E22-E23-E25 -> 29151 | F43: =F22-F23-F25 -> 24274 | G43: =G22-G23-G25 -> 23651
A44: NWC % of revenue | B44: =B43/B9 -> 0.16253284 | C44: =C43/C9 -> 0.13820998 | D44: =D43/D9 -> 0.15359038 | E44: =E43/E9 -> 0.18969871 | F44: =F43/F9 -> 0.14892938 | G44: =G43/G9 -> 0.13238735
...

Sheet Profit & Loss
A1: {='Data Sheet'!B1} -> INFOSYS LTD | H1: {='Data Sheet'!$E$1} | M1: SCREENER.IN
A3: Narration | B3: {='Data Sheet'!B12} -> 42825 | C3: {='Data Sheet'!C12} -> 43190 | D3: {='Data Sheet'!D12} -> 43555 | E3: {='Data Sheet'!E12} -> 43921 | F3: {='Data Sheet'!F12} -> 44286 | G3: {='Data Sheet'!G12} -> 44651 | H3: {='Data Sheet'!H12} -> 45016 | I3: {='Data Sheet'!I12} -> 45382 | ... K3: {='Data Sheet'!K12} -> 46112 | L3: Trailing | M3: Best Case | N3: Worst Case
A4: Sales | B4: {='Data Sheet'!B13} -> 68484 | C4: {='Data Sheet'!C13} -> 70522 | D4: {='Data Sheet'!D13} -> 82675 | E4: {='Data Sheet'!E13} -> 90791 | F4: {='Data Sheet'!F13} -> 100472 | G4: {='Data Sheet'!G13} -> 121641 | H4: {='Data Sheet'!H13} -> 146767 | I4: {='Data Sheet'!I13} -> 153670 | ... K4: {='Data Sheet'!K13} -> 178650 | M4: {=$K4+G22*K4} -> 195814.61 | N4: {=$K4+H22*L4} -> 178650
A5: Expenses | B5: {=SUM('Data Sheet'!B14,'Data Sheet'!B16:B20,-1*'Data Sheet'!B15)} -> 49880 | C5: {=SUM('Data Sheet'!C14,'Data Sheet'!C16:C20,-1*'Data Sheet'!C15)} -> 51700 | D5: {=SUM('Data Sheet'!D14,'Data Sheet'!D16:D20,-1*'Data Sheet'!D15)} -> 62505 | E5: {=SUM('Data Sheet'!E14,'Data Sheet'!E16:E20,-1*'Data Sheet'!E15)} -> 68524 | F5: {=SUM('Data Sheet'!F14,'Data Sheet'!F16:F20,-1*'Data Sheet'!F15)} -> 72583 | G5: {=SUM('Data Sheet'!G14,'Data Sheet'!G16:G20,-1*'Data Sheet'!G15)} -> 90150 | H5: {=SUM('Data Sheet'!H14,'Data Sheet'!H16:H20,-1*'Data Sheet'!H15)} -> 111637 | I5: {=SUM('Data Sheet'!I14,'Data Sheet'!I16:I20,-1*'Data Sheet'!I15)} -> 117245 | ... K5: {=SUM('Data Sheet'!K14,'Data Sheet'!K16:K20,-1*'Data Sheet'!K15)} -> 136370 | M5: {=M4-M6} -> 149188.11 | N5: {=N4-N6} -> 178650
A6: Operating Profit | B6: {=B4-B5} -> 18604 | C6: {=C4-C5} -> 18822 | D6: {=D4-D5} -> 20170 | E6: {=E4-E5} -> 22267 | F6: {=F4-F5} -> 27889 | G6: {=G4-G5} -> 31491 | H6: {=H4-H5} -> 35130 | I6: {=I4-I5} -> 36425 | ... K6: {=K4-K5} -> 42280 | M6: {=M4*G23} -> 46626.497 | N6: {=N4*H23} -> 0
A7: Other Income | B7: {='Data Sheet'!B21} -> 3050 | C7: {='Data Sheet'!C21} -> 3311 | D7: {='Data Sheet'!D21} -> 2882 | E7: {='Data Sheet'!E21} -> 2803 | F7: {='Data Sheet'!F21} -> 2201 | G7: {='Data Sheet'!G21} -> 2295 | H7: {='Data Sheet'!H21} -> 2701 | I7: {='Data Sheet'!I21} -> 4711 | ... K7: {='Data Sheet'!K21} -> 3033 | M7: 0 | N7: 0
A8: Depreciation | B8: {='Data Sheet'!B22} -> 1703 | C8: {='Data Sheet'!C22} -> 1863 | D8: {='Data Sheet'!D22} -> 2011 | E8: {='Data Sheet'!E22} -> 2893 | F8: {='Data Sheet'!F22} -> 3267 | G8: {='Data Sheet'!G22} -> 3476 | H8: {='Data Sheet'!H22} -> 4225 | I8: {='Data Sheet'!I22} -> 4678 | ... K8: {='Data Sheet'!K22} -> 4902 | M8: =$L8 -> 0 | N8: =$L8 -> 0
A9: Interest | B9: ='Data Sheet'!B23 -> 0 | C9: ='Data Sheet'!C23 -> 0 | D9: ='Data Sheet'!D23 -> 0 | E9: {='Data Sheet'!E23} -> 170 | F9: {='Data Sheet'!F23} -> 195 | G9: {='Data Sheet'!G23} -> 200 | H9: {='Data Sheet'!H23} -> 284 | I9: {='Data Sheet'!I23} -> 470 | J9: {='Data Sheet'!J23} -> 416 | K9: {='Data Sheet'!K23} -> 416 | M9: =$L9 -> 0 | N9: =$L9 -> 0
A10: Profit before tax | B10: {='Data Sheet'!B24} -> 19951 | C10: {='Data Sheet'!C24} -> 20270 | D10: {='Data Sheet'!D24} -> 21041 | E10: {='Data Sheet'!E24} -> 22007 | F10: {='Data Sheet'!F24} -> 26628 | G10: {='Data Sheet'!G24} -> 30110 | H10: {='Data Sheet'!H24} -> 33322 | I10: {='Data Sheet'!I24} -> 35988 | ... K10: {='Data Sheet'!K24} -> 39995 | M10: {=M6+M7-SUM(M8:M9)} -> 46626.497 | N10: {=N6+N7-SUM(N8:N9)} -> 0
A11: Tax | B11: {='Data Sheet'!B25} -> 5598 | C11: {='Data Sheet'!C25} -> 4241 | D11: {='Data Sheet'!D25} -> 5631 | E11: {='Data Sheet'!E25} -> 5368 | F11: {='Data Sheet'!F25} -> 7205 | G11: {='Data Sheet'!G25} -> 7964 | H11: {='Data Sheet'!H25} -> 9214 | I11: {='Data Sheet'!I25} -> 9740 | ... K11: {='Data Sheet'!K25} -> 10521 | M11: {=IF($L10>0,$L11/$L10,0)} -> 0 | N11: {=IF($L10>0,$L11/$L10,0)} -> 0
A12: Net profit | B12: {='Data Sheet'!B26} -> 14353 | C12: {='Data Sheet'!C26} -> 16029 | D12: {='Data Sheet'!D26} -> 15404 | E12: {='Data Sheet'!E26} -> 16594 | F12: {='Data Sheet'!F26} -> 19351 | G12: {='Data Sheet'!G26} -> 22110 | H12: {='Data Sheet'!H26} -> 24095 | I12: {='Data Sheet'!I26} -> 26233 | ... K12: {='Data Sheet'!K26} -> 29440 | M12: {=M10-M11*M10} -> 46626.497 | N12: {=N10-N11*N10} -> 0
A13: EPS | B13: {=IF('Data Sheet'!B93>0,B12/'Data Sheet'!B93,0)} -> 31.243606 | C13: {=IF('Data Sheet'!C93>0,C12/'Data Sheet'!C93,0)} -> 36.694748 | D13: {=IF('Data Sheet'!D93>0,D12/'Data Sheet'!D93,0)} -> 35.258303 | E13: {=IF('Data Sheet'!E93>0,E12/'Data Sheet'!E93,0)} -> 38.962198 | F13: {=IF('Data Sheet'!F93>0,F12/'Data Sheet'!F93,0)} -> 45.41742 | G13: {=IF('Data Sheet'!G93>0,G12/'Data Sheet'!G93,0)} -> 52.559013 | H13: {=IF('Data Sheet'!H93>0,H12/'Data Sheet'!H93,0)} -> 58.079834 | I13: {=IF('Data Sheet'!I93>0,I12/'Data Sheet'!I93,0)} -> 63.198343 | ... K13: {=IF('Data Sheet'!K93>0,K12/'Data Sheet'!K93,0)} -> 72.590985 | L13: {=IF('Data Sheet'!$B6>0,L12/'Data Sheet'!$B6,0)} -> 0 | M13: {=IF('Data Sheet'!$B6>0,M12/'Data Sheet'!$B6,0)} -> 114.89236 | N13: {=IF('Data Sheet'!$B6>0,N12/'Data Sheet'!$B6,0)} -> 0
A14: Price to earning | B14: {=IF(B15>0,B15/B13,"")} -> 16.359507 | C14: {=IF(C15>0,C15/C13,"")} -> 15.421825 | D14: {=IF(D15>0,D15/D13,"")} -> 21.097158 | E14: {=IF(E15>0,E15/E13,"")} -> 16.464677 | F14: {=IF(F15>0,F15/F13,"")} -> 30.121702 | G14: {=IF(G15>0,G15/G13,"")} -> 36.280171 | H14: {=IF(H15>0,H15/H13,"")} -> 24.585986 | I14: {=IF(I15>0,I15/I13,"")} -> 23.703944 | ... K14: {=IF(K15>0,K15/K13,"")} -> 17.228035 | L14: {=IF(L13>0,L15/L13,0)} -> 0 | M14: {=G24} -> 21.784075 | N14: {=H24} -> 0
A15: Price | B15: {='Data Sheet'!B90} -> 511.13 | C15: {='Data Sheet'!C90} -> 565.9 | D15: {='Data Sheet'!D90} -> 743.85 | E15: {='Data Sheet'!E90} -> 641.5 | F15: {='Data Sheet'!F90} -> 1368.05 | G15: {='Data Sheet'!G90} -> 1906.85 | H15: {='Data Sheet'!H90} -> 1427.95 | I15: {='Data Sheet'!I90} -> 1498.05 | ... K15: {='Data Sheet'!K90} -> 1250.6 | L15: {='Data Sheet'!B8} -> 1035 | M15: {=M13*M14} -> 2502.8238 | N15: {=N13*N14} -> 0
A17: RATIOS:
A18: Dividend Payout | B18: {=IF('Data Sheet'!B26>0,'Data Sheet'!B27/'Data Sheet'!B26,0)} -> 0.41047865 | C18: {=IF('Data Sheet'!C26>0,'Data Sheet'!C27/'Data Sheet'!C26,0)} -> 0.59052966 | D18: {=IF('Data Sheet'!D26>0,'Data Sheet'!D27/'Data Sheet'!D26,0)} -> 0.59870813 | E18: {=IF('Data Sheet'!E26>0,'Data Sheet'!E27/'Data Sheet'!E26,0)} -> 0.44757141 | F18: {=IF('Data Sheet'!F26>0,'Data Sheet'!F27/'Data Sheet'!F26,0)} -> 0.59271355 | G18: {=IF('Data Sheet'!G26>0,'Data Sheet'!G27/'Data Sheet'!G26,0)} -> 0.58831298 | H18: {=IF('Data Sheet'!H26>0,'Data Sheet'!H27/'Data Sheet'!H26,0)} -> 0.58390537 | I18: {=IF('Data Sheet'!I26>0,'Data Sheet'!I27/'Data Sheet'!I26,0)} -> 0.72630656 | ... K18: {=IF('Data Sheet'!K26>0,'Data Sheet'!K27/'Data Sheet'!K26,0)} -> 0.66
A19: OPM | B19: {=IF(B6>0,B6/B4,0)} -> 0.27165469 | C19: {=IF(C6>0,C6/C4,0)} -> 0.26689544 | D19: {=IF(D6>0,D6/D4,0)} -> 0.24396734 | E19: {=IF(E6>0,E6/E4,0)} -> 0.24525559 | F19: {=IF(F6>0,F6/F4,0)} -> 0.27757982 | G19: {=IF(G6>0,G6/G4,0)} -> 0.25888475 | H19: {=IF(H6>0,H6/H4,0)} -> 0.23935898 | I19: {=IF(I6>0,I6/I4,0)} -> 0.2370339 | ... L19: {=IF(L6>0,L6/L4,0)} -> 0
A21: TRENDS | B21: 10 YEARS | C21: 7 YEARS | D21: 5 YEARS | E21: 3 YEARS | F21: RECENT | G21: BEST | H21: WORST
A22: Sales Growth | B22: {=IF(B4=0,"",POWER($K4/B4,1/9)-1)} -> 0.11241852 | C22: {=IF(D4=0,"",POWER($K4/D4,1/7)-1)} -> 0.11635961 | D22: {=IF(F4=0,"",POWER($K4/F4,1/5)-1)} -> 0.12199674 | E22: {=IF(H4=0,"",POWER($K4/H4,1/3)-1)} -> 0.067722024 | F22: {=IF(ISERROR(MAX(IF(J4=0,"",(K4-J4)/J4),IF(K4=0,"",(L4-K4)/K4))),"",MAX(IF(J4=0,"",(K4-J4)/J4),IF(K4=0,"",(L4-K4)/K4)))} -> 0.096079514 | G22: {=MAX(E22:F22)} -> 0.096079514 | H22: {=MIN(B22:F22)} -> 0.067722024
A23: OPM | B23: {=IF(SUM(B4:$K$4)=0,"",SUMPRODUCT(B19:$K$19,B4:$K$4)/SUM(B4:$K$4))} -> 0.24842648 | C23: {=IF(SUM(E4:$K$4)=0,"",SUMPRODUCT(E19:$K$19,E4:$K$4)/SUM(E4:$K$4))} -> 0.2457829 | D23: {=IF(SUM(G4:$K$4)=0,"",SUMPRODUCT(G19:$K$19,G4:$K$4)/SUM(G4:$K$4))} -> 0.2416625 | E23: {=IF(SUM(I4:$K$4)=0,"",SUMPRODUCT(I19:$K$19,I4:$K$4)/SUM(I4:$K$4))} -> 0.23811552 | F23: {=L19} -> 0 | G23: {=MAX(E23:F23)} -> 0.23811552 | H23: {=MIN(B23:F23)} -> 0
A24: Price to Earning | B24: {=IF(ISERROR(AVERAGEIF(B14:$L14,">0")),"",AVERAGEIF(B14:$L14,">0"))} -> 22.568325 | C24: {=IF(ISERROR(AVERAGEIF(E14:$L14,">0")),"",AVERAGEIF(E14:$L14,">0"))} -> 24.686395 | D24: {=IF(ISERROR(AVERAGEIF(G14:$L14,">0")),"",AVERAGEIF(G14:$L14,">0"))} -> 25.243677 | E24: {=IF(ISERROR(AVERAGEIF(I14:$L14,">0")),"",AVERAGEIF(I14:$L14,">0"))} -> 21.784075 | F24: {=L14} -> 0 | G24: {=MAX(E24:F24)} -> 21.784075 | H24: {=MIN(B24:F24)} -> 0

Sheet Quarters
A1: {='Profit & Loss'!A1} -> INFOSYS LTD | E1: {='Data Sheet'!$E$1} | J1: SCREENER.IN
A3: Narration | B3: {='Data Sheet'!B30} -> 45382 | C3: {='Data Sheet'!C30} -> 45473 | D3: {='Data Sheet'!D30} -> 45565 | E3: {='Data Sheet'!E30} -> 45657 | F3: {='Data Sheet'!F30} -> 45747 | G3: {='Data Sheet'!G30} -> 45838 | H3: {='Data Sheet'!H30} -> 45930 | I3: {='Data Sheet'!I30} -> 46022 | ... K3: {='Data Sheet'!K30} -> 46203
A4: Sales | B4: {='Data Sheet'!B31} -> 37923 | C4: {='Data Sheet'!C31} -> 39315 | D4: {='Data Sheet'!D31} -> 40986 | E4: {='Data Sheet'!E31} -> 41764 | F4: {='Data Sheet'!F31} -> 40925 | G4: {='Data Sheet'!G31} -> 42279 | H4: {='Data Sheet'!H31} -> 44490 | I4: {='Data Sheet'!I31} -> 45479 | ... K4: {='Data Sheet'!K31} -> 48211
A5: Expenses | B5: {='Data Sheet'!B32} -> 29139 | C5: {='Data Sheet'!C32} -> 29878 | D5: {='Data Sheet'!D32} -> 31177 | E5: {='Data Sheet'!E32} -> 31649 | F5: {='Data Sheet'!F32} -> 31051 | G5: {='Data Sheet'!G32} -> 32336 | H5: {='Data Sheet'!H32} -> 33955 | I5: {='Data Sheet'!I32} -> 34845 | ... K5: {='Data Sheet'!K32} -> 36802
A6: Operating Profit | B6: {='Data Sheet'!B39} -> 8784 | C6: {='Data Sheet'!C39} -> 9437 | D6: {='Data Sheet'!D39} -> 9809 | E6: {='Data Sheet'!E39} -> 10115 | F6: {='Data Sheet'!F39} -> 9874 | G6: {='Data Sheet'!G39} -> 9943 | H6: {='Data Sheet'!H39} -> 10535 | I6: {='Data Sheet'!I39} -> 10634 | ... K6: {='Data Sheet'!K39} -> 11409
A7: Other Income | B7: {='Data Sheet'!B33} -> 2729 | C7: {='Data Sheet'!C33} -> 838 | D7: {='Data Sheet'!D33} -> 712 | E7: {='Data Sheet'!E33} -> 859 | F7: {='Data Sheet'!F33} -> 1190 | G7: {='Data Sheet'!G33} -> 1042 | H7: {='Data Sheet'!H33} -> 982 | I7: {='Data Sheet'!I33} -> -150 | ... K7: {='Data Sheet'!K33} -> 984
A8: Depreciation | B8: {='Data Sheet'!B34} -> 1163 | C8: {='Data Sheet'!C34} -> 1149 | D8: {='Data Sheet'!D34} -> 1160 | E8: {='Data Sheet'!E34} -> 1203 | F8: {='Data Sheet'!F34} -> 1299 | G8: {='Data Sheet'!G34} -> 1140 | H8: {='Data Sheet'!H34} -> 1182 | I8: {='Data Sheet'!I34} -> 1155 | ... K8: {='Data Sheet'!K34} -> 1246
A9: Interest | B9: {='Data Sheet'!B35} -> 110 | C9: {='Data Sheet'!C35} -> 105 | D9: {='Data Sheet'!D35} -> 108 | E9: {='Data Sheet'!E35} -> 101 | F9: {='Data Sheet'!F35} -> 102 | G9: {='Data Sheet'!G35} -> 105 | H9: {='Data Sheet'!H35} -> 106 | I9: {='Data Sheet'!I35} -> 100 | ... K9: {='Data Sheet'!K35} -> 119
A10: Profit before tax | B10: {='Data Sheet'!B36} -> 10240 | C10: {='Data Sheet'!C36} -> 9021 | D10: {='Data Sheet'!D36} -> 9253 | E10: {='Data Sheet'!E36} -> 9670 | F10: {='Data Sheet'!F36} -> 9663 | G10: {='Data Sheet'!G36} -> 9740 | H10: {='Data Sheet'!H36} -> 10229 | I10: {='Data Sheet'!I36} -> 9229 | ... K10: {='Data Sheet'!K36} -> 11028
A11: Tax | B11: {='Data Sheet'!B37} -> 2265 | C11: {='Data Sheet'!C37} -> 2647 | D11: {='Data Sheet'!D37} -> 2737 | E11: {='Data Sheet'!E37} -> 2848 | F11: {='Data Sheet'!F37} -> 2625 | G11: {='Data Sheet'!G37} -> 2816 | H11: {='Data Sheet'!H37} -> 2854 | I11: {='Data Sheet'!I37} -> 2563 | ... K11: {='Data Sheet'!K37} -> 3253
A12: Net profit | B12: {='Data Sheet'!B38} -> 7969 | C12: {='Data Sheet'!C38} -> 6368 | D12: {='Data Sheet'!D38} -> 6506 | E12: {='Data Sheet'!E38} -> 6806 | F12: {='Data Sheet'!F38} -> 7033 | G12: {='Data Sheet'!G38} -> 6921 | H12: {='Data Sheet'!H38} -> 7364 | I12: {='Data Sheet'!I38} -> 6654 | ... K12: {='Data Sheet'!K38} -> 7769
A14: OPM | B14: {=IF(B4>0,B6/B4,"")} -> 0.23162724 | C14: {=IF(C4>0,C6/C4,"")} -> 0.24003561 | D14: {=IF(D4>0,D6/D4,"")} -> 0.23932562 | E14: {=IF(E4>0,E6/E4,"")} -> 0.24219423 | F14: {=IF(F4>0,F6/F4,"")} -> 0.24127062 | G14: {=IF(G4>0,G6/G4,"")} -> 0.23517586 | H14: {=IF(H4>0,H6/H4,"")} -> 0.23679479 | I14: {=IF(I4>0,I6/I4,"")} -> 0.2338222 | ... K14: {=IF(K4>0,K6/K4,"")} -> 0.23664724

Sheet Balance Sheet
A1: {='Profit & Loss'!A1} -> INFOSYS LTD | E1: {='Data Sheet'!$E$1} | J1: SCREENER.IN
A3: Narration | B3: {='Data Sheet'!B42} -> 42825 | C3: {='Data Sheet'!C42} -> 43190 | D3: {='Data Sheet'!D42} -> 43555 | E3: {='Data Sheet'!E42} -> 43921 | F3: {='Data Sheet'!F42} -> 44286 | G3: {='Data Sheet'!G42} -> 44651 | H3: {='Data Sheet'!H42} -> 45016 | I3: {='Data Sheet'!I42} -> 45382 | ... K3: {='Data Sheet'!K42} -> 46112
A4: Equity Share Capital | B4: {='Data Sheet'!B43} -> 1144 | C4: {='Data Sheet'!C43} -> 1088 | D4: {='Data Sheet'!D43} -> 2170 | E4: {='Data Sheet'!E43} -> 2122 | F4: {='Data Sheet'!F43} -> 2124 | G4: {='Data Sheet'!G43} -> 2098 | H4: {='Data Sheet'!H43} -> 2069 | I4: {='Data Sheet'!I43} -> 2071 | ... K4: {='Data Sheet'!K43} -> 2024
A5: Reserves | B5: {='Data Sheet'!B44} -> 67838 | C5: {='Data Sheet'!C44} -> 63835 | D5: {='Data Sheet'!D44} -> 62778 | E5: {='Data Sheet'!E44} -> 63328 | F5: {='Data Sheet'!F44} -> 74227 | G5: {='Data Sheet'!G44} -> 73252 | H5: {='Data Sheet'!H44} -> 73338 | I5: {='Data Sheet'!I44} -> 86045 | ... K5: {='Data Sheet'!K44} -> 90828
A6: Borrowings | B6: ='Data Sheet'!B45 -> 0 | C6: ='Data Sheet'!C45 -> 0 | D6: ='Data Sheet'!D45 -> 0 | E6: {='Data Sheet'!E45} -> 4633 | F6: {='Data Sheet'!F45} -> 5325 | G6: {='Data Sheet'!G45} -> 5474 | H6: {='Data Sheet'!H45} -> 8299 | I6: {='Data Sheet'!I45} -> 8359 | J6: {='Data Sheet'!J45} -> 8227 | K6: {='Data Sheet'!K45} -> 9176
A7: Other Liabilities | B7: {='Data Sheet'!B46} -> 14166 | C7: {='Data Sheet'!C46} -> 14426 | D7: {='Data Sheet'!D46} -> 19118 | E7: {='Data Sheet'!E46} -> 21717 | F7: {='Data Sheet'!F46} -> 25835 | G7: {='Data Sheet'!G46} -> 35905 | H7: {='Data Sheet'!H46} -> 40890 | I7: {='Data Sheet'!I46} -> 39545 | ... K7: {='Data Sheet'!K46} -> 52260
A8: Total | B8: {='Data Sheet'!B47} -> 83148 | C8: {='Data Sheet'!C47} -> 79349 | D8: {='Data Sheet'!D47} -> 84066 | E8: {='Data Sheet'!E47} -> 91800 | F8: {='Data Sheet'!F47} -> 107511 | G8: {='Data Sheet'!G47} -> 116729 | H8: {='Data Sheet'!H47} -> 124596 | I8: {='Data Sheet'!I47} -> 136020 | ... K8: {='Data Sheet'!K47} -> 154288
A10: Net Block | B10: {='Data Sheet'!B48} -> 14179 | C10: {='Data Sheet'!C48} -> 12574 | D10: {='Data Sheet'!D48} -> 15710 | E10: {='Data Sheet'!E48} -> 23789 | F10: {='Data Sheet'!F48} -> 25505 | G10: {='Data Sheet'!G48} -> 25800 | H10: {='Data Sheet'!H48} -> 29225 | I10: {='Data Sheet'!I48} -> 27622 | ... K10: {='Data Sheet'!K48} -> 33770
A11: Capital Work in Progress | B11: {='Data Sheet'!B49} -> 1365 | C11: {='Data Sheet'!C49} -> 1606 | D11: {='Data Sheet'!D49} -> 1388 | E11: {='Data Sheet'!E49} -> 954 | F11: {='Data Sheet'!F49} -> 922 | G11: {='Data Sheet'!G49} -> 416 | H11: {='Data Sheet'!H49} -> 288 | I11: {='Data Sheet'!I49} -> 293 | ... K11: {='Data Sheet'!K49} -> 526
A12: Investments | B12: {='Data Sheet'!B50} -> 16423 | C12: {='Data Sheet'!C50} -> 12163 | D12: {='Data Sheet'!D50} -> 11261 | E12: {='Data Sheet'!E50} -> 8792 | F12: {='Data Sheet'!F50} -> 14205 | G12: {='Data Sheet'!G50} -> 20324 | H12: {='Data Sheet'!H50} -> 19478 | I12: {='Data Sheet'!I50} -> 24623 | ... K12: {='Data Sheet'!K50} -> 21880
A13: Other Assets | B13: {='Data Sheet'!B51} -> 51181 | C13: {='Data Sheet'!C51} -> 53006 | D13: {='Data Sheet'!D51} -> 55707 | E13: {='Data Sheet'!E51} -> 58265 | F13: {='Data Sheet'!F51} -> 66879 | G13: {='Data Sheet'!G51} -> 70189 | H13: {='Data Sheet'!H51} -> 75605 | I13: {='Data Sheet'!I51} -> 83482 | ... K13: {='Data Sheet'!K51} -> 98112
A14: Total | B14: {='Data Sheet'!B52} -> 83148 | C14: {='Data Sheet'!C52} -> 79349 | D14: {='Data Sheet'!D52} -> 84066 | E14: {='Data Sheet'!E52} -> 91800 | F14: {='Data Sheet'!F52} -> 107511 | G14: {='Data Sheet'!G52} -> 116729 | H14: {='Data Sheet'!H52} -> 124596 | I14: {='Data Sheet'!I52} -> 136020 | ... K14: {='Data Sheet'!K52} -> 154288
A16: Working Capital | B16: {=B13-B7} -> 37015 | C16: {=C13-C7} -> 38580 | D16: {=D13-D7} -> 36589 | E16: {=E13-E7} -> 36548 | F16: {=F13-F7} -> 41044 | G16: {=G13-G7} -> 34284 | H16: {=H13-H7} -> 34715 | I16: {=I13-I7} -> 43937 | ... K16: {=K13-K7} -> 45852
A17: Debtors | B17: {='Data Sheet'!B53} -> 12322 | C17: {='Data Sheet'!C53} -> 13142 | D17: {='Data Sheet'!D53} -> 14827 | E17: {='Data Sheet'!E53} -> 18487 | F17: {='Data Sheet'!F53} -> 19294 | G17: {='Data Sheet'!G53} -> 22698 | H17: {='Data Sheet'!H53} -> 25424 | I17: {='Data Sheet'!I53} -> 30193 | ... K17: {='Data Sheet'!K53} -> 35234
A18: Inventory | B18: ='Data Sheet'!B54 -> 0 | C18: ='Data Sheet'!C54 -> 0 | D18: ='Data Sheet'!D54 -> 0 | E18: ='Data Sheet'!E54 -> 0 | F18: ='Data Sheet'!F54 -> 0 | G18: ='Data Sheet'!G54 -> 0 | H18: ='Data Sheet'!H54 -> 0 | I18: ='Data Sheet'!I54 -> 0 | ... K18: ='Data Sheet'!K54 -> 0
A20: Debtor Days | B20: {=IF('Profit & Loss'!B4>0,B17/('Profit & Loss'!B4/365),0)} -> 65.672712 | C20: {=IF('Profit & Loss'!C4>0,C17/('Profit & Loss'!C4/365),0)} -> 68.018916 | D20: {=IF('Profit & Loss'!D4>0,D17/('Profit & Loss'!D4/365),0)} -> 65.459389 | E20: {=IF('Profit & Loss'!E4>0,E17/('Profit & Loss'!E4/365),0)} -> 74.321849 | F20: {=IF('Profit & Loss'!F4>0,F17/('Profit & Loss'!F4/365),0)} -> 70.092265 | G20: {=IF('Profit & Loss'!G4>0,G17/('Profit & Loss'!G4/365),0)} -> 68.108368 | H20: {=IF('Profit & Loss'!H4>0,H17/('Profit & Loss'!H4/365),0)} -> 63.227837 | I20: {=IF('Profit & Loss'!I4>0,I17/('Profit & Loss'!I4/365),0)} -> 71.715006 | ... K20: {=IF('Profit & Loss'!K4>0,K17/('Profit & Loss'!K4/365),0)} -> 71.986622
A21: Inventory Turnover | B21: {=IF(B18>0,'Profit & Loss'!B4/B18,0)} -> 0 | C21: {=IF(C18>0,'Profit & Loss'!C4/C18,0)} -> 0 | D21: {=IF(D18>0,'Profit & Loss'!D4/D18,0)} -> 0 | E21: {=IF(E18>0,'Profit & Loss'!E4/E18,0)} -> 0 | F21: {=IF(F18>0,'Profit & Loss'!F4/F18,0)} -> 0 | G21: {=IF(G18>0,'Profit & Loss'!G4/G18,0)} -> 0 | H21: {=IF(H18>0,'Profit & Loss'!H4/H18,0)} -> 0 | I21: {=IF(I18>0,'Profit & Loss'!I4/I18,0)} -> 0 | ... K21: {=IF(K18>0,'Profit & Loss'!K4/K18,0)} -> 0
A23: Return on Equity | B23: {=IF(SUM(B4:B5)>0,'Profit & Loss'!B12/SUM(B4:B5),"")} -> 0.20806877 | C23: {=IF(SUM(C4:C5)>0,'Profit & Loss'!C12/SUM(C4:C5),"")} -> 0.24689247 | D23: {=IF(SUM(D4:D5)>0,'Profit & Loss'!D12/SUM(D4:D5),"")} -> 0.23717435 | E23: {=IF(SUM(E4:E5)>0,'Profit & Loss'!E12/SUM(E4:E5),"")} -> 0.25353705 | F23: {=IF(SUM(F4:F5)>0,'Profit & Loss'!F12/SUM(F4:F5),"")} -> 0.25344789 | G23: {=IF(SUM(G4:G5)>0,'Profit & Loss'!G12/SUM(G4:G5),"")} -> 0.29343066 | H23: {=IF(SUM(H4:H5)>0,'Profit & Loss'!H12/SUM(H4:H5),"")} -> 0.31953267 | I23: {=IF(SUM(I4:I5)>0,'Profit & Loss'!I12/SUM(I4:I5),"")} -> 0.29770984 | ... K23: {=IF(SUM(K4:K5)>0,'Profit & Loss'!K12/SUM(K4:K5),"")} -> 0.31706371
A24: Return on Capital Emp | C24: {=IF((B4+B5+B6+C4+C5+C6)>0,('Profit & Loss'!C10+'Profit & Loss'!C9)*2/(B4+B5+B6+C4+C5+C6),"")} -> 0.30275195 | D24: {=IF((C4+C5+C6+D4+D5+D6)>0,('Profit & Loss'!D10+'Profit & Loss'!D9)*2/(C4+C5+C6+D4+D5+D6),"")} -> 0.32402923 | E24: {=IF((D4+D5+D6+E4+E5+E6)>0,('Profit & Loss'!E10+'Profit & Loss'!E9)*2/(D4+D5+D6+E4+E5+E6),"")} -> 0.32847272 | F24: {=IF((E4+E5+E6+F4+F5+F6)>0,('Profit & Loss'!F10+'Profit & Loss'!F9)*2/(E4+E5+E6+F4+F5+F6),"")} -> 0.35349469 | G24: {=IF((F4+F5+F6+G4+G5+G6)>0,('Profit & Loss'!G10+'Profit & Loss'!G9)*2/(F4+F5+F6+G4+G5+G6),"")} -> 0.37304615 | H24: {=IF((G4+G5+G6+H4+H5+H6)>0,('Profit & Loss'!H10+'Profit & Loss'!H9)*2/(G4+G5+G6+H4+H5+H6),"")} -> 0.40850909 | I24: {=IF((H4+H5+H6+I4+I5+I6)>0,('Profit & Loss'!I10+'Profit & Loss'!I9)*2/(H4+H5+H6+I4+I5+I6),"")} -> 0.40468196 | J24: {=IF((I4+I5+I6+J4+J5+J6)>0,('Profit & Loss'!J10+'Profit & Loss'!J9)*2/(I4+I5+I6+J4+J5+J6),"")} -> 0.37925394 | K24: {=IF((J4+J5+J6+K4+K5+K6)>0,('Profit & Loss'!K10+'Profit & Loss'!K9)*2/(J4+J5+J6+K4+K5+K6),"")} -> 0.39220082

Sheet Cash Flow
A1: {='Balance Sheet'!A1} -> INFOSYS LTD | E1: {='Data Sheet'!$E$1} | J1: SCREENER.IN
A3: Narration | B3: {='Data Sheet'!B81} -> 42825 | C3: {='Data Sheet'!C81} -> 43190 | D3: {='Data Sheet'!D81} -> 43555 | E3: {='Data Sheet'!E81} -> 43921 | F3: {='Data Sheet'!F81} -> 44286 | G3: {='Data Sheet'!G81} -> 44651 | H3: {='Data Sheet'!H81} -> 45016 | I3: {='Data Sheet'!I81} -> 45382 | ... K3: {='Data Sheet'!K81} -> 46112
A4: Cash from Operating Activity | B4: {='Data Sheet'!B82} -> 11531 | C4: {='Data Sheet'!C82} -> 13218 | D4: {='Data Sheet'!D82} -> 14841 | E4: {='Data Sheet'!E82} -> 17003 | F4: {='Data Sheet'!F82} -> 23224 | G4: {='Data Sheet'!G82} -> 23885 | H4: {='Data Sheet'!H82} -> 22467 | I4: {='Data Sheet'!I82} -> 25210 | ... K4: {='Data Sheet'!K82} -> 33986
A5: Cash from Investing Activity | B5: {='Data Sheet'!B83} -> -14664 | C5: {='Data Sheet'!C83} -> 4533 | D5: {='Data Sheet'!D83} -> -632 | E5: {='Data Sheet'!E83} -> -331 | F5: {='Data Sheet'!F83} -> -7373 | G5: {='Data Sheet'!G83} -> -6485 | H5: {='Data Sheet'!H83} -> -1071 | I5: {='Data Sheet'!I83} -> -5093 | ... K5: {='Data Sheet'!K83} -> 3546
A6: Cash from Financing Activity | B6: {='Data Sheet'!B84} -> -6939 | C6: {='Data Sheet'!C84} -> -20505 | D6: {='Data Sheet'!D84} -> -14512 | E6: {='Data Sheet'!E84} -> -17591 | F6: {='Data Sheet'!F84} -> -9786 | G6: {='Data Sheet'!G84} -> -24642 | H6: {='Data Sheet'!H84} -> -26695 | I6: {='Data Sheet'!I84} -> -17504 | ... K6: {='Data Sheet'!K84} -> -39786
A7: Net Cash Flow | B7: {='Data Sheet'!B85} -> -10072 | C7: {='Data Sheet'!C85} -> -2754 | D7: {='Data Sheet'!D85} -> -303 | E7: {='Data Sheet'!E85} -> -919 | F7: {='Data Sheet'!F85} -> 6065 | G7: {='Data Sheet'!G85} -> -7242 | H7: {='Data Sheet'!H85} -> -5299 | I7: {='Data Sheet'!I85} -> 2613 | ... K7: {='Data Sheet'!K85} -> -2254

Sheet Data Sheet
A1: COMPANY NAME | B1: INFOSYS LTD | E1: {=IF(B2<>B3,"A NEW VERSION OF THE WORKSHEET IS AVAILABLE","")}
A2: LATEST VERSION | B2: 2.1
A3: CURRENT VERSION | B3: 2.1
A5: META
A6: Number of shares | B6: {=IF(B9>0,B9/B8,0)} -> 405.82766
A7: Face Value | B7: 5
A8: Current Price | B8: 1035
A9: Market Capitalization | B9: 420031.63
A11: PROFIT & LOSS
A12: Report Date | B12: 42825 | C12: 43190 | D12: 43555 | E12: 43921 | F12: 44286 | G12: 44651 | H12: 45016 | I12: 45382 | J12: 45747 | K12: 46112
A13: Sales | B13: 68484 | C13: 70522 | D13: 82675 | E13: 90791 | F13: 100472 | G13: 121641 | H13: 146767 | I13: 153670 | J13: 162990 | K13: 178650
A14: Raw Material Cost
A15: Change in Inventory
A16: Power and Fuel | B16: 228 | C16: 207 | D16: 221 | E16: 229 | F16: 143 | G16: 132 | H16: 176 | I16: 199 | J16: 222 | K16: 223
A17: Other Mfr. Exp | B17: 6712 | C17: 7286 | D17: 9902 | E17: 11086 | F17: 12800 | G17: 20690 | H17: 26330 | I17: 27195 | J17: 30395 | K17: 32922
A18: Employee Cost | B18: 37669 | C18: 38902 | D18: 45323 | E18: 50895 | F18: 55547 | G18: 63997 | H18: 78374 | I18: 82636 | J18: 85968 | K18: 95112
A19: Selling and admin | B19: 4584 | C19: 4585 | D19: 5553 | E19: 5375 | F19: 3194 | G19: 4305 | H19: 5300 | I19: 5705 | J19: 6039 | K19: 6784
A20: Other Expenses | B20: 687 | C20: 720 | D20: 1506 | E20: 939 | F20: 899 | G20: 1026 | H20: 1457 | I20: 1510 | J20: 1130 | K20: 1329
A21: Other Income | B21: 3050 | C21: 3311 | D21: 2882 | E21: 2803 | F21: 2201 | G21: 2295 | H21: 2701 | I21: 4711 | J21: 3600 | K21: 3033
A22: Depreciation | B22: 1703 | C22: 1863 | D22: 2011 | E22: 2893 | F22: 3267 | G22: 3476 | H22: 4225 | I22: 4678 | J22: 4812 | K22: 4902
A23: Interest | E23: 170 | F23: 195 | G23: 200 | H23: 284 | I23: 470 | J23: 416 | K23: 416
A24: Profit before tax | B24: 19951 | C24: 20270 | D24: 21041 | E24: 22007 | F24: 26628 | G24: 30110 | H24: 33322 | I24: 35988 | J24: 37608 | K24: 39995
A25: Tax | B25: 5598 | C25: 4241 | D25: 5631 | E25: 5368 | F25: 7205 | G25: 7964 | H25: 9214 | I25: 9740 | J25: 10858 | K25: 10521
A26: Net profit | B26: 14353 | C26: 16029 | D26: 15404 | E26: 16594 | F26: 19351 | G26: 22110 | H26: 24095 | I26: 26233 | J26: 26713 | K26: 29440
A27: Dividend Amount | B27: 5891.6 | C27: 9465.6 | D27: 9222.5 | E27: 7427 | F27: 11469.6 | G27: 13007.6 | H27: 14069.2 | I27: 19053.2 | J27: 17827.8 | K27: 19430.4
A29: QUARTERS
A30: Report Date | B30: 45382 | C30: 45473 | D30: 45565 | E30: 45657 | F30: 45747 | G30: 45838 | H30: 45930 | I30: 46022 | J30: 46112 | K30: 46203
A31: Sales | B31: 37923 | C31: 39315 | D31: 40986 | E31: 41764 | F31: 40925 | G31: 42279 | H31: 44490 | I31: 45479 | J31: 46402 | K31: 48211
A32: Expenses | B32: 29139 | C32: 29878 | D32: 31177 | E32: 31649 | F32: 31051 | G32: 32336 | H32: 33955 | I32: 34845 | J32: 35235 | K32: 36802
A33: Other Income | B33: 2729 | C33: 838 | D33: 712 | E33: 859 | F33: 1190 | G33: 1042 | H33: 982 | I33: -150 | J33: 1159 | K33: 984
A34: Depreciation | B34: 1163 | C34: 1149 | D34: 1160 | E34: 1203 | F34: 1299 | G34: 1140 | H34: 1182 | I34: 1155 | J34: 1424 | K34: 1246
A35: Interest | B35: 110 | C35: 105 | D35: 108 | E35: 101 | F35: 102 | G35: 105 | H35: 106 | I35: 100 | J35: 105 | K35: 119
A36: Profit before tax | B36: 10240 | C36: 9021 | D36: 9253 | E36: 9670 | F36: 9663 | G36: 9740 | H36: 10229 | I36: 9229 | J36: 10797 | K36: 11028
A37: Tax | B37: 2265 | C37: 2647 | D37: 2737 | E37: 2848 | F37: 2625 | G37: 2816 | H37: 2854 | I37: 2563 | J37: 2288 | K37: 3253
A38: Net profit | B38: 7969 | C38: 6368 | D38: 6506 | E38: 6806 | F38: 7033 | G38: 6921 | H38: 7364 | I38: 6654 | J38: 8501 | K38: 7769
A39: Operating Profit | B39: 8784 | C39: 9437 | D39: 9809 | E39: 10115 | F39: 9874 | G39: 9943 | H39: 10535 | I39: 10634 | J39: 11167 | K39: 11409
A41: BALANCE SHEET
A42: Report Date | B42: 42825 | C42: 43190 | D42: 43555 | E42: 43921 | F42: 44286 | G42: 44651 | H42: 45016 | I42: 45382 | J42: 45747 | K42: 46112
A43: Equity Share Capital | B43: 1144 | C43: 1088 | D43: 2170 | E43: 2122 | F43: 2124 | G43: 2098 | H43: 2069 | I43: 2071 | J43: 2073 | K43: 2024
A44: Reserves | B44: 67838 | C44: 63835 | D44: 62778 | E44: 63328 | F44: 74227 | G44: 73252 | H44: 73338 | I44: 86045 | J44: 93745 | K44: 90828
...
